<?xml version="1.0"?>
<!-- Simplified Humanoid Robot URDF for VLA Educational Module -->
<robot name="vla_humanoid">

  <!-- Base Link -->
  <link name="base_link">
    <visual>
      <geometry>
        <box size="0.4 0.3 0.6"/>
      </geometry>
      <material name="blue">
        <color rgba="0.2 0.4 0.8 1.0"/>
      </material>
    </visual>
    <collision>
      <geometry>
        <box size="0.4 0.3 0.6"/>
      </geometry>
    </collision>
    <inertial>
      <mass value="50.0"/>
      <inertia ixx="2.5" ixy="0.0" ixz="0.0" iyy="3.0" iyz="0.0" izz="1.5"/>
    </inertial>
  </link>

  <!-- Head Link (for camera) -->
  <link name="head">
    <visual>
      <geometry>
        <sphere radius="0.15"/>
      </geometry>
      <material name="gray">
        <color rgba="0.7 0.7 0.7 1.0"/>
      </material>
    </visual>
    <collision>
      <geometry>
        <sphere radius="0.15"/>
      </geometry>
    </collision>
    <inertial>
      <mass value="5.0"/>
      <inertia ixx="0.05" ixy="0.0" ixz="0.0" iyy="0.05" iyz="0.0" izz="0.05"/>
    </inertial>
  </link>

  <joint name="head_joint" type="revolute">
    <parent link="base_link"/>
    <child link="head"/>
    <origin xyz="0 0 0.4" rpy="0 0 0"/>
    <axis xyz="0 0 1"/>
    <limit lower="-1.57" upper="1.57" effort="10.0" velocity="1.0"/>
  </joint>

  <!-- Right Arm -->
  <link name="right_arm">
    <visual>
      <geometry>
        <cylinder length="0.5" radius="0.05"/>
      </geometry>
      <material name="gray">
        <color rgba="0.7 0.7 0.7 1.0"/>
      </material>
    </visual>
    <collision>
      <geometry>
        <cylinder length="0.5" radius="0.05"/>
      </geometry>
    </collision>
    <inertial>
      <mass value="3.0"/>
      <inertia ixx="0.06" ixy="0.0" ixz="0.0" iyy="0.06" iyz="0.0" izz="0.01"/>
    </inertial>
  </link>

  <joint name="right_shoulder" type="revolute">
    <parent link="base_link"/>
    <child link="right_arm"/>
    <origin xyz="0.25 0 0.15" rpy="0 1.57 0"/>
    <axis xyz="0 1 0"/>
    <limit lower="-3.14" upper="3.14" effort="20.0" velocity="2.0"/>
  </joint>

  <!-- Left Arm -->
  <link name="left_arm">
    <visual>
      <geometry>
        <cylinder length="0.5" radius="0.05"/>
      </geometry>
      <material name="gray">
        <color rgba="0.7 0.7 0.7 1.0"/>
      </material>
    </visual>
    <collision>
      <geometry>
        <cylinder length="0.5" radius="0.05"/>
      </geometry>
    </collision>
    <inertial>
      <mass value="3.0"/>
      <inertia ixx="0.06" ixy="0.0" ixz="0.0" iyy="0.06" iyz="0.0" izz="0.01"/>
    </inertial>
  </link>

  <joint name="left_shoulder" type="revolute">
    <parent link="base_link"/>
    <child link="left_arm"/>
    <origin xyz="-0.25 0 0.15" rpy="0 1.57 0"/>
    <axis xyz="0 1 0"/>
    <limit lower="-3.14" upper="3.14" effort="20.0" velocity="2.0"/>
  </joint>

  <!-- Camera (RGB-D) -->
  <link name="camera_link">
    <visual>
      <geometry>
        <box size="0.05 0.15 0.05"/>
      </geometry>
      <material name="black">
        <color rgba="0.1 0.1 0.1 1.0"/>
      </material>
    </visual>
    <inertial>
      <mass value="0.5"/>
      <inertia ixx="0.001" ixy="0.0" ixz="0.0" iyy="0.001" iyz="0.0" izz="0.001"/>
    </inertial>
  </link>

  <joint name="camera_joint" type="fixed">
    <parent link="head"/>
    <child link="camera_link"/>
    <origin xyz="0.1 0 0" rpy="0 0 0"/>
  </joint>

  <!-- Gazebo Camera Plugin -->
  <gazebo reference="camera_link">
    <sensor type="depth" name="camera">
      <update_rate>30.0</update_rate>
      <camera name="head_camera">
        <horizontal_fov>1.3962634</horizontal_fov>
        <image>
          <width>640</width>
          <height>480</height>
          <format>R8G8B8</format>
        </image>
        <clip>
          <near>0.1</near>
          <far>10.0</far>
        </clip>
      </camera>
      <plugin name="camera_controller" filename="libgazebo_ros_camera.so">
        <ros>
          <namespace>/vla_humanoid</namespace>
          <argument>image_raw:=rgb/image_raw</argument>
          <argument>camera_info:=rgb/camera_info</argument>
          <argument>depth/image_raw:=depth/image_raw</argument>
        </ros>
        <camera_name>camera</camera_name>
        <frame_name>camera_link</frame_name>
      </plugin>
    </sensor>
  </gazebo>

  <!-- Base Colors -->
  <gazebo reference="base_link">
    <material>Gazebo/Blue</material>
  </gazebo>

  <gazebo reference="head">
    <material>Gazebo/Gray</material>
  </gazebo>

</robot>
